<?xml version="1.0"?>
<robot name="raspicat_wheel" xmlns:xacro="http://ros.org/wiki/xacro">
  <xacro:include filename="$(find raspicat_description)/urdf/wheel/wheel.gazebo.xacro"/>

  <xacro:macro name="wheel" params="prefix parent *joint_origin *joint_axis">
    <joint name="${prefix}_wheel_joint" type="continuous">
      <xacro:insert_block name="joint_origin"/>
      <xacro:insert_block name="joint_axis"/>
      <parent link="${parent}"/>
      <child link="${prefix}_wheel_link"/>
    </joint>
    <link name="${prefix}_wheel_link">
      <visual>
        <origin xyz="0 0 0" rpy="0 0 0"/>
        <geometry>
          <mesh filename="package://raspicat_description/meshes/dae/wheel/raspicat_wheel.dae"/>
        </geometry>
      </visual>
      <collision>
        <origin xyz="0 0 0" rpy="0 0 0"/>
        <geometry>
          <cylinder radius="${wheel_radius}" length="${wheel_length}"/>
        </geometry>
      </collision>
      <inertial>
        <origin xyz="0 0 0" rpy="0 0 0"/>
        <mass value="${wheel_mass}"/>
        <inertia ixx="0.000382815198" ixy="-0.000000043013" ixz="0.000000027406"
                 iyy="0.00038254522"  iyz="0.00000018751" 
                 izz="0.00074855867"/>
      </inertial>
    </link>
  </xacro:macro>
</robot>