<?xml version="1.0"?>
<robot name="raspicat_caster" xmlns:xacro="http://ros.org/wiki/xacro">
  <xacro:include filename="$(find raspicat_description)/urdf/caster/caster.gazebo.xacro"/>

  <xacro:macro name="caster" params="parent *joint_origin *joint_axis">
    <joint name="caster_joint" type="continuous">
      <xacro:insert_block name="joint_origin"/>
      <xacro:insert_block name="joint_axis"/>
      <parent link="${parent}"/>
      <child link="caster_link"/>
    </joint>
    <link name="caster_link">
      <visual>
        <origin xyz="0 0 0" rpy="0 0 0"/>
        <geometry>
          <mesh filename="package://raspicat_description/meshes/dae/caster/raspicat_caster.dae"/>
        </geometry>
      </visual>
      <collision>
        <origin xyz="0 0 0" rpy="0 0 0"/>
        <geometry>
          <mesh filename="package://raspicat_description/meshes/dae/caster/raspicat_caster.dae"/>
        </geometry>
      </collision>
        <inertial>
          <origin xyz="0 0 0" rpy="0 0 0"/>
          <mass value="${caster_mass}"/>
          <inertia ixx="0.000688529016" ixy="0" ixz="-0.00026266676"
                   iyy="0.000802824209"  iyz="0" 
                   izz="0.000410878112"/>
        </inertial>
    </link>
  </xacro:macro>

  <xacro:macro name="caster_wheel" params="parent *joint_origin *joint_axis">
    <joint name="caster_wheel_joint" type="continuous">
      <xacro:insert_block name="joint_origin"/>
      <xacro:insert_block name="joint_axis"/>
      <parent link="${parent}"/>
      <child link="caster_wheel_link"/>
    </joint>
    <link name="caster_wheel_link">
      <visual>
        <origin xyz="0 0 0" rpy="0 0 0"/>
        <geometry>
          <mesh filename="package://raspicat_description/meshes/dae/caster/raspicat_caster_wheel.dae"/>
        </geometry>
      </visual>
      <collision>
        <origin xyz="0 0 0" rpy="0 0 0"/>
        <geometry>
          <cylinder radius="${caster_radius}" length="${caster_length}"/>
        </geometry>
      </collision>
      <inertial>
        <origin xyz="0 0 0" rpy="0 0 0"/>
        <mass value="${caster_mass}"/>
        <inertia ixx="0.000382815198" ixy="-0.000000043013" ixz="0.000000027406"
                 iyy="0.00038254522"  iyz="0.00000018751" 
                 izz="0.00074855867"/>
      </inertial>
    </link>
  </xacro:macro>
</robot>
